Workbook

Sheet Änderungshistorie
A1: Version | B1: Datum | C1: Name | D1: Was
A2: _2020-07-06 | B2: 43989 | C2: D.Schrader | D2: Actualisation according the Conzept for Dokumentation Testautmation
A3: _2020-07-07 | B3: 44019 | C3: Swarna Srivastava | D3: Updated TA Status
A4: _2020-07-08 | B4: 44050 | C4: Swarna Srivastava | D4: Updated TA Status and cell colours for Section/Section Items
A5: _2020-07-10 | B5: 44111 | C5: Swarna Srivastava | D5: Replaced Missing Items with Open in TA Status column
A6: _2020-07-16 | B6: 16/7/2020 | C6: Swarna Srivastava | D6: Updated TA status for previously open items that are now completed
A7: _2020-08-10 | B7: 44053 | C7: Christine Ganz | D7: Editorial Page ( Checkpoints in red, One-HUB-EP-13 to One-HUB-EP-24 changed to "modified"; added S109 Answers Stage deleting section), Deleting S120, S124 and S106 ,
A8: _2020-08-20 | B8: 20/8/2020 | C8: Swarna Srivastava | D8: Updated TA status for previously open items that are now completed
A9: _2020-08-31 | B9: 31/8/2020 | C9: Swarna Srivastava | D9: Updated TA status for previously open items that are now completed
A10: _2020-09-18 | B10: 44092 | C10: Christine Ganz | D10: XF Template (Checkpoints added, Column TA and TA Status added) please add TA Testcase marked as TA = yes and TA Status open)
D11: also new is checkpoint: ONE-HUB-XF-17
A12: _2020-09-25 | B12: 25/9/2020 | C12: Swarna Srivastava | D12: All the tests are impletented in each page. Previously sections present in multiple pages were implemented in 1 page only
A13: _2020-10-08 | B13: 44112 | C13: Christine Ganz | D13: Hompage: One-HUB-HP-09; One-HUB-HP-18; One-HUB-HP-27 -> a new Section S129
B14: 44112 | C14: Christine Ganz | D14: Homepage: The Checkpoint from HP changed because of the new Section
B15: 44112 | C15: Christine Ganz | D15: Showroompage: One-HUB-SR-06; One-HUB-SR-18; One-HUB-SR-30 -> Section S102 modified
B16: 44112 | C16: Christine Ganz | D16: Showroompage: One-HUB-SR-12; One-HUB-SR-24; One-HUB-SR-36 -> new Section S130
B17: 44112 | C17: Christine Ganz | D17: Showroompage: The Checkpoint from SP changed because of the new Section
B18: 44112 | C18: Christine Ganz | D18: Editorial Overview Page: The Checkpoint has been updated (there was a wrong sequence)
B19: 44112 | C19: Christine Ganz | D19: Editorail Page: One-HUB-EP-11; One-HUB-EP-23; One-HUB-EP-35; Countdown Section has been modified because of new elemnts: Icon Bullet Point
B20: 44112 | C20: Christine Ganz | D20: New Templates: Glossay Page and Maintain Glossary Page: 7 new TC for TA
B21: 44112 | C21: Christine Ganz | D21: XF Template: ONE-HUB-XF-11, new Disclaimer Type
B22: 44112 | C22: Christine Ganz | D22: XF Template: The Checkpoint from XF' changed because of the new Disclaime type
A23: _2020-10-16 | B23: 16/10/2020 | C23: Amruta Mhatre | D23: Updated TA Status: Editorail Page: One-HUB-EP-11; One-HUB-EP-23; One-HUB-EP-35
A24: _2020-10-22 | B24: 22/10/2020 | C24: Amruta Mhatre | D24: Updated TA Status: Showroompage: One-HUB-SR-06; One-HUB-SR-18; One-HUB-SR-30 -> Section S102 modified
A25: _2020-10-22 | B25: 22/10/2020 | C25: Amruta Mhatre | D25: Updated TA Status: Showroompage: One-HUB-SR-12; One-HUB-SR-36 -> new Section S130
A26: _2020-10-22 | B26: 22/10/2020 | C26: Amruta Mhatre | D26: Updated TA Status: XFs : ONE-HUB-XF-01, ONE-HUB-XF-03, ONE-HUB-XF-05, ONE-HUB-XF-07, ONE-HUB-XF-09, ONE-HUB-XF-11, ONE-HUB-XF-20
A27: _2020-10-23 | B27: 23/10/2020 | C27: Amruta Mhatre | D27: Updated TA Status: Hompage: One-HUB-HP-09; One-HUB-HP-18; One-HUB-HP-27 -> a new Section S129
B28: 44200 | C28: Dagmar Schrader | D28: Update color blue to black; Insert column "TA"; Split Column "TA Status" into "TA" and"TA Status"; Update Browser Matrix
B29: 44224 | C29: Dagmar Schrader | D29: Seperate Publisher proves in own checkpoint to make transparent which checkpoint are automated for the diffenet Dekstop and mobil divices
B30: 44229 | C30: Aditya Pandey | D30: Updated Home Page, Showroom page, Editorial Overview Page and Editorial Page with completed new verification and delete testcases for different viewports
B31: 44245 | C31: Christine Ganz | D31: Update: Template To-Sit --> general functions: Testgoal and TA + TA Status
A32: _2021-04-01 | B32: 44287 | C32: Jens Vogler | D32: Prototype documentation of clickable items (Home Page 27 TF)
A33: _2021-04-20 | B33: 44306 | C33: William Pacori | D33: Add Video asset + cover image in S104
A34: _2021-04-21 | B34: 44307 | C34: Swarna Srivastava | D34: Completed "is saved" open items
A35: _2021-04-27 | B35: 44313 | C35: Christine Ganz | D35: Template Homepage: New checkpoints: One-HUB-HP-28, One-HUB-HP-29, One-HUB-HP-29-01, One-HUB-HP-30, One-HUB-HP-30-01, Adjustment of some Sections: Clickable Elements should be add to TA Tests(marked orange)
B36: 44313 | C36: Christine Ganz | D36: Template Showroom: Adjustment of some Sections: Clickable Elements should be add to TA Tests(marked orange)
B37: 44313 | C37: Christine Ganz | D37: Template Editorial Overview Page: Adjustment of some Sections: Clickable Elements should be add to TA Tests(marked orange)
B38: 44313 | C38: Christine Ganz | D38: Template Editorial Page: Adjustment of some Sections: Clickable Elements should be add to TA Tests(marked orange)
B39: 44313 | C39: Christine Ganz | D39: Template Error Page (all checkpoints) adding Tests to TA
B40: 44313 | C40: Christine Ganz | D40: Template XF's: ONE-HUB-XF-14 to ONE-HUB-XF-27
...

Sheet Teststrategie
A1: Teststrategie | E1: Aufteilung
A2: 1. Auf dem Publisher über Domänen-URL einen exemplarischen Markt testen | E2: 0.8
A3: 2.E2E: Im Autor exemplarisch Testconten verändern/aufbauen, publishen, auf Publisher testen | E3: 0.2
A6: Glossar:
A10: Shown are only the moste important Sections per page. These are suggested by PO Support by using the Actual live content as reference.
A12: Site Root
A13: Market Page
B14: Home Page*
C15: Model Overview Page *
D16: Showroompage*
C17: Editorial Overview Page *
D18: Editorial Overview Page* | E18: Editorial Page*
D19: Showroompage*
D20: Integrator Page
D21: Editorial Page*
C22: Editorial Page* | D22: Structure Page
D23: Modelstructure Root
D24: Disclaimer Overview Page
D25: Unsupported Browser Notification
C26: Structure Page
D27: Error Page 4xx*
D28: Non React Simple Page
O31: Homepage
O32: Editorial Page
O33: Editorial Overview Page
O34: Model Overview Page
O35: Showroom Page
O36: Error Page
O41: Non React Simple Page
O42: Structure Page
O43: Glossary Page
O44: Maintain Glossary Page
O45: Structure Page
O46: Feature App Page

Sheet MetaData
A1: Tablename | B1: #Checkpoint | C1: #TA Completed | D1: Automatisierungsgrad
A2: Homepage | B2: =COUNTIF(INDIRECT("'" & A2 & "'!A" &(MATCH("Checkpoint",INDIRECT("'" & A2 & "'!A:A"),0)+1)& ":A1000"),"?*") -> 51 | C2: =COUNTIF(INDIRECT("'" & A2 & "'!G:G"),"*Completed*") -> 48 | D2: =C2/B2 -> 0.94117647
A3: Showroom Page | B3: =COUNTIF(INDIRECT("'" & A3 & "'!A" &(MATCH("Checkpoint",INDIRECT("'" & A3 & "'!A:A"),0)+1)& ":A1000"),"?*") -> 75 | C3: =COUNTIF(INDIRECT("'" & A3 & "'!G:G"),"*Completed*") -> 73 | D3: =C3/B3 -> 0.97333333
A4: Editorial Overview Page | B4: =COUNTIF(INDIRECT("'" & A4 & "'!A" &(MATCH("Checkpoint",INDIRECT("'" & A4 & "'!A:A"),0)+1)& ":A1000"),"?*") -> 51 | C4: =COUNTIF(INDIRECT("'" & A4 & "'!G:G"),"*Completed*") -> 50 | D4: =C4/B4 -> 0.98039216
A5: Editorial Page | B5: =COUNTIF(INDIRECT("'" & A5 & "'!A" &(MATCH("Checkpoint",INDIRECT("'" & A5 & "'!A:A"),0)+1)& ":A1000"),"?*") -> 61 | C5: =COUNTIF(INDIRECT("'" & A5 & "'!G:G"),"*Completed*") -> 60 | D5: =C5/B5 -> 0.98360656
A6: Model Overview Page | B6: =COUNTIF(INDIRECT("'" & A6 & "'!A" &(MATCH("Checkpoint",INDIRECT("'" & A6 & "'!A:A"),0)+1)& ":A1000"),"?*") -> 1 | C6: =COUNTIF(INDIRECT("'" & A6 & "'!G:G"),"*Completed*") -> 0 | D6: =C6/B6 -> 0
A7: Feature App Page | B7: =COUNTIF(INDIRECT("'" & A7 & "'!A" &(MATCH("Checkpoint",INDIRECT("'" & A7 & "'!A:A"),0)+1)& ":A1000"),"?*") -> 3 | C7: =COUNTIF(INDIRECT("'" & A7 & "'!G:G"),"*Completed*") -> 3 | D7: =C7/B7 -> 1
A8: DAM | B8: =COUNTIF(INDIRECT("'" & A8 & "'!A" &(MATCH("Checkpoint",INDIRECT("'" & A8 & "'!A:A"),0)+1)& ":A1000"),"?*") -> 4 | C8: =COUNTIF(INDIRECT("'" & A8 & "'!G:G"),"*Completed*") -> 0 | D8: =C8/B8 -> 0
A9: Error Page | B9: =COUNTIF(INDIRECT("'" & A9 & "'!A" &(MATCH("Checkpoint",INDIRECT("'" & A9 & "'!A:A"),0)+1)& ":A1000"),"?*") -> 10 | C9: =COUNTIF(INDIRECT("'" & A9 & "'!G:G"),"*Completed*") -> 9 | D9: =C9/B9 -> 0.9
A10: XFs | B10: =COUNTIF(INDIRECT("'" & A10 & "'!A" &(MATCH("Checkpoint",INDIRECT("'" & A10 & "'!A:A"),0)+1)& ":A1000"),"?*") -> 33 | C10: =COUNTIF(INDIRECT("'" & A10 & "'!G:G"),"*Completed*") -> 24 | D10: =C10/B10 -> 0.72727273
A11: TO SIT | B11: =COUNTIF(INDIRECT("'" & A11 & "'!A" &(MATCH("Checkpoint",INDIRECT("'" & A11 & "'!A:A"),0)+1)& ":A1000"),"?*") -> 28 | C11: =COUNTIF(INDIRECT("'" & A11 & "'!G:G"),"*Completed*") -> 19 | D11: =C11/B11 -> 0.67857143
A12: Summe | B12: =SUBTOTAL(109,Tabelle2['#Checkpoint]) -> 317 | C12: =SUBTOTAL(109,Tabelle2['#TA Completed]) -> 286 | D12: =Tabelle2[[#Totals],['#TA Completed]]/Tabelle2[[#Totals],['#Checkpoint]] -> 0.9022082

Sheet Homepage
A1: Testexecution Product Release Version: v3.198.276.122 Date Start: 30.06.2026 Date Ende: 06.07.2026 Test
A2: Environment: https://ngw-stage.lighthouselabs.io/de/mofa.html
A3: Checkpoint | B3: Template | C3: Section | D3: Test goal (expected result) | E3: Section Items | F3: TA | G3: TA Status | H3: Example | I3: URL Testcontent | J3: Who | K3: iPhone 16 iOs v. 26 Safari/Mobile | L3: iPad iOs v. 26 Safari/Tablet | M3: MacBook Safari v. 12.1.2 | N3: Samsung Galaxy 8 Android v. IE v. 10.1.00.27 Chrome/Mobile | O3: Tablet Android v. Chrome v. 77 Chrome/Tablet | P3: Samsung Galaxy 8 Android Chrome v. 77 Chrome/Mobile | Q3: Chrome v. 84 Chrome/Desktop | R3: Microsoft Edge v. 44 Chrome/ Desktop | S3: FireFox v. 68 | T3: New Jira Ticket | U3: Existing Jira Ticket
A4: One-HUB-HP-01 | B4: Home Page | C4: S139 Basic Stage Section | D4: Validation, that - a S139 with its items can be created - arranges a headline, a media element, a copy item and two optional CTA Button - is saved | E4: S139 Fullscreen Stage Section Item: Heading Item: Image Item: I101Copy Item Item: CTA Button with Link or Layer Item: CTA Button with Link or Layer | F4: Yes | G4: Completed | Q4: TA OK | S4: TA OK
A5: One-HUB-HP-02 | B5: Home Page | C5: S113 First Level Teaser | D5: Validation, that - a S113 with its items can be created - arranges a headline and between 2 and 4 Editorial Teaser Elements | E5: S113 First Level Teaser Item: Heading Editorial Teaser Element 1 Editorial Teaser Element 2 Editorial Teaser Element 3 Editorial Teaser Element 4 | F5: Yes | G5: Completed | Q5: TA OK | S5: TA OK
A6: One-HUB-HP-03 | B6: Home Page | C6: S116 Section Group | D6: Validation, that - a S116 with its items can be created - arranges a headline and several sections | E6: S116 Section Group S115 Focus Teaser Section S110 Highlight Teaser Section S102 Single Column Section (all Items) Item: Heading I101 Copy Item I102 Quote Item I103 Statement Item I106 Media Single Item I108 Link List Item | F6: Yes | G6: Completed | Q6: TA OK | S6: TA OK
A7: One-HUB-HP-04 | B7: Home Page | C7: S115 Focus Teaser Section | D7: Validation, that - a S115 with its items can be created - arranges a focus teaser element | E7: S115 Focus Teaser Section Editorial Teaser Element 1 Item: Additional Link | F7: Yes | G7: Completed | Q7: TA OK | S7: TA OK
A8: One-HUB-HP-05 | B8: Home Page | C8: S110 Highlight Teaser Section | D8: Validation, that - a S110 with its items can be created - arranges between 3 and 5 Editorial Teaser Elements | E8: S110 Highlight Teaser Section Editorial Teaser Element 1 Editorial Teaser Element 2 Editorial Teaser Element 3 | F8: Yes | G8: completed | Q8: TA OK | S8: TA OK
A9: One-HUB-HP-06 | B9: Home Page | C9: S102 Single Column Section | D9: Validation, that - a S102 with its items can be created - arranges a headline and a column for items - Items: I101 copy item; I102 quote item;I103 statement item;I106 media single item ;I126 link list item | E9: S102 Single Column Section Item: Heading I101 Copy Item I102 Quote Item I103 Statement Item I106 Media Single Item I108 Link List Item | F9: Yes | G9: completed | Q9: TA OK | S9: TA OK
A10: One-HUB-HP-07 | B10: Home Page | C10: S108 Editorial Teaser Section | D10: Validation, that - a S108 with its items can be created - arranges 3 or 6 teaser elements - is saved | E10: S108 Editorial Teaser Section Item: Heading Editorial Teaser Element 1 Editorial Teaser Element 2 Editorial Teaser Element 3 Editorial Teaser Element 4 Editorial Teaser Element 5 Editorial Teaser Element 6 | F10: Yes | G10: completed | Q10: TA OK | S10: TA OK
A11: One-HUB-HP-08 | B11: Home Page | C11: S119 Newsletter Signup Section | D11: Validation, that - a S119 with its items can be created - arranges a headline, a copy item and a CTA Button which provides a link to a newsletter signup form | E11: S119 Newsletter Signup Section Item: Heading Item: I101Copy Item CTA Button | F11: Yes | G11: completed | Q11: TA OK | S11: TA OK
A12: One-HUB-HP-09 | B12: Home Page | C12: S129 Power Teaser Section | D12: Validation, that - a S108 with its items can be created - arranges 3 or 6 teaser elements | E12: S129 Power Teaser Section Item: Richtext Simple Item: Heading Item: I101Copy Item Icon Bullet Point Element 1: with CAR_FRONT Icon Icon Bullet Point Element 2: with CONTACT_DEALER Icon Icon Bullet Point Element 3: with DOWNLOAD Icon Icon Bullet Point Element 4: with MAIL Icon Icon Bullet Point Element 5: with CALENDAR Icon Icon Bullet Point Element 6: with BROCHURE Icon CTA Button Image | F12: Yes | G12: completed | Q12: TA OK | S12: TA OK
A13: One-HUB-HP-28 | B13: Home Page | C13: S132 Expand Collapse Section | D13: Validation, that - a S132 with its items can be created - arraganges I132 Expand Collapse Items | E13: Item: I132 Expand Collapse Item 1 Item: Image Item: Richtext Simple Item: Richtext Full Item: Link Item: I132 Expand Collapse Item 2 Item: Image Item: Richtext Simple Item: Richtext Full Item: Link Item: I132 Expand Collapse Item 3 Item: Image Item: Richtext Simple Item: Richtext Full Item: Link Item: I132 Expand Collapse Item 4 Item: Image Item: Richtext Simple Item: Richtext Full Item: Link | F13: Yes | G13: Completed | Q13: TA OK | S13: TA OK
A14: One-HUB-HP-10 | B14: Home Page | C14: S139 Fullscreen Stage Section | D14: Validation, that - a S139 with its items can be modified - arranges a headline, a media element, a copy item and an two optional CTA Button | E14: S139 Fullscreen Stage Section Item: Heading Item: Image Item: I101Copy Item Item: CTA Button with Link or Layer Item: CTA Button with Link or Layer | F14: Yes | G14: Completed | Q14: TA OK | S14: TA OK
A15: One-HUB-HP-10-01 | B15: Home Page | C15: S139 Fullscreen Stage Section | D15: Validation, that - the S139 Fullscreen Stage Section is displayed on the publisher - Both CTA Buttons with Link or Layer are clickable | E15: S104 Fullscreen Stage Section Item: Heading Item: Image Item: I101Copy Item Item: CTA Button with Link or Layer Item: CTA Button with Link or Layer | F15: Yes | G15: Completed | Q15: TA OK | S15: TA OK
... A53: One-HUB-HP-30-01 | B53: Home Page | C53: S132 Expand Collapse Section | D53: Validation, that - the Home Page is displayed without S132 Power Teaser Section on the publisher | E53: Item: I132 Expand Collapse Item 1 Item: Image Item: Richtext Simple Item: Richtext Full Item: Link Item: I132 Expand Collapse Item 2 Item: Image Item: Richtext Simple Item: Richtext Full Item: Link Item: I132 Expand Collapse Item 3 Item: Image Item: Richtext Simple Item: Richtext Full Item: Link Item: I132 Expand Collapse Item 4 Item: Image Item: Richtext Simple Item: Richtext Full Item: Link | F53: Yes | G53: Completed | Q53: TA OK | S53: TA OK
A54: One-HUB-HP-31 | B54: Accessibility | C54: Accessiblity | D54: Validation, that - all elements are reachable via keyboard - every element is read out by a screenreader | F54: No

Sheet Editorial Overview Page
A1: =Homepage!A1 -> Testexecution Product Release Version: v3.198.276.122 Date Start: 30.06.2026 Date Ende: 06.07.2026 Test
A2: =Homepage!A2 -> Environment: https://ngw-stage.lighthouselabs.io/de/mofa.html
A3: Checkpoint | B3: Template | C3: Section | D3: Test goal (expected result) | E3: Section Items | F3: TA | G3: TA Status | H3: Example | I3: URL Testcontent | J3: Who | K3: iPhone 16 iOs v. 26 Safari/Mobile | L3: iPad iOs v. 26 Safari/Tablet | M3: MacBook Safari v. 12.1.2 | N3: Samsung Galaxy 8 Android v. IE v. 10.1.00.27 Chrome/Mobile | O3: Tablet Android v. Chrome v. 77 Chrome/Tablet | P3: Samsung Galaxy 8 Android Chrome v. 77 Chrome/Mobile | Q3: Chrome v. 84 Chrome/Desktop | R3: Microsoft Edge v. 44 Chrome/ Desktop | S3: FireFox v. 68 | T3: New Jira Ticket | U3: Existing Jira Ticket
A4: One-HUB-EOP-01 | B4: Editorial Overview Page | C4: S106 Editorial Stage Section | D4: Validation, that - a S106 with its items can be created - arranges a headline, a media element and a copy item - is saved | E4: S106 Editorial Stage Section Item: Media Element Item: Heading Item: I101Copy Item | F4: Yes | G4: Completed | Q4: TA OK | S4: TA OK
A5: One-HUB-EOP-02 | B5: Editorial Overview Page | C5: S113 First Level Teaser | D5: Validation, that - a S113 with its items can be created - arranges a headline and between 2 and 4 Editorial Teaser Elements - is saved | E5: S113 First Level Teaser Item: Heading Editorial Teaser Element 1 Editorial Teaser Element 2 | F5: Yes | G5: Completed | Q5: TA OK | S5: TA OK
A6: One-HUB-EOP-03 | B6: Editorial Overview Page | C6: S115 Focus Teaser Section | D6: Validation, that - a S115 with its items can be created - arranges a focus teaser element - is saved | E6: S115 Focus Teaser Section Editorial Teaser Element 1 | F6: Yes | G6: Completed | Q6: TA OK | S6: TA OK
A7: One-HUB-EOP-04 | B7: Editorial Overview Page | C7: S123 Second Level Teaser Section | D7: Validation, that - a S123 with its items can be created - arranges an optional heading, copy item and a grid-like view of teasers - is saved | E7: S123 Second Level Teaser Section Item: Heading Item: I101Copy Item Item: grid-like view teaser | F7: Yes | G7: Completed | Q7: TA OK | S7: TA OK
A8: One-HUB-EOP-05 | B8: Editorial Overview Page | C8: S116 Section Group | D8: Validation, that - a S116 with its items can be created - arranges a headline and sections - is saved | E8: S116 Section Group S108 Editorial Teaser Section Item: Heading Item: Editorial teaser 1 Item: Editorial teaser 2 Item: Editorial teaser 3 S101 Heading Section Item: Heading Item: I101Copy Item | F8: Yes | G8: Completed | Q8: TA OK | S8: TA OK
A9: One-HUB-EOP-06 | B9: Editorial Overview Page | C9: S117 Accordion Section | D9: Validation, that - a S117 with its items can be created - arranges a I117 accordion item - is saved | E9: S117 Accordion Section Item: Heading Item: I117Accordion Item 1 Item: Richtext Simple Item: Richtext Full Item: I117Accordion Item 2 Item: Richtext Simple Item: Richtext Full Item: I117Accordion Item 3 Item: Richtext Simple Item: Richtext Full | F9: Yes | G9: Completed | Q9: TA OK | S9: TA OK
A10: One-HUB-EOP-07 | B10: Editorial Overview Page | C10: S124 Table Section | D10: Validation, that - a S124 with its cells can be created - arranges empty table, image table, merge column merge row and richtext table cell - is saved | E10: S124 Table Section Row Table Element 1: with 4 Richtext Table Cells Row Table Element 2: with 4 Empty Table Cells Row Table Element 3: with 4 Richtext Table Cells Row Table Element 4: with 4 Image Table Cells | F10: Yes | G10: Completed | Q10: TA OK | S10: TA OK
A11: One-HUB-EOP-08 | B11: Editorial Overview Page | C11: S126 Iframe Integrator Section | D11: Validation, that - a S126 with its items can be created - integrates an external website in a page - is saved | E11: S126 Iframe Integrator Section Item: external URL - https://webspecial.volkswagen.de/emobility/test-lsf - https://trml1m.axshare.com/#id=fup9js&p=page_1&c=1 - https://hef7jn.axshare.com/#id=ptypxa&p=page_1&c=1 Item: Iframe heights by breakpoints Item: Layout for the column | F11: Yes | G11: Completed | Q11: TA OK | S11: TA OK
A12: One-HUB-EOP-09 | B12: Editorial Overview Page | C12: S111 Pros and Cons Section | D12: Validation, that - a S111 with its items can be created - arranges a pro / contra item with a headline, copy item, label, statement, description and image - is saved | E12: S111 Pros and Cons Sectio Item: Heading n Pro/Contra item Item: I101Copy Item Item: Richtext Simple Item: Richtext Simple Item: Richtext Simple Item: Richtext Simple Item: Richtext Full Item: image | F12: Yes | G12: Completed | Q12: TA OK | S12: TA OK
A13: One-HUB-EOP-10 | B13: Editorial Overview Page | C13: S112 Step By Step Section | D13: Validation, that - a S112 with its items can be created - arranges a headline, copy item and I111 Step by Step Containerchild - is saved | E13: S112 Step By Step Section Item: Heading Item: I101Copy Item Item: StepbyStep Item 1 StepbyStep Item: Image StepbyStep Item: Richtext Simple Element StepbyStep Item: Richtext Full Item: StepbyStep Item 2 StepbyStep Item: Image StepbyStep Item: Richtext Full Item: StepbyStep Item 3 StepbyStep Item: Image StepbyStep Item: Richtext Full | F13: Yes | G13: Completed | Q13: TA OK | S13: TA OK
A14: One-HUB-EOP-11 | B14: Editorial Overview Page | C14: S106 Editorial Stage Section | D14: Validation, that - a S106 with its items can be modify - arranges a headline, a media element and a copy item | E14: S106 Editorial Stage Section Item: Media Element Item: Heading Item: I101Copy Item | F14: Yes | G14: Completed | Q14: TA OK | S14: TA OK
A15: One-HUB-EOP-11-01 | B15: Editorial Overview Page | C15: S106 Editorial Stage Section | D15: Validation, that - the S106 Editorial Stage Section is displayed on the publisher | E15: S106 Editorial Stage Section Item: Media Element Item: Heading Item: I101Copy Item | F15: Yes | G15: Completed | K15: TA OK | L15: TA OK | M15: TA OK | N15: TA OK | O15: TA OK | P15: TA OK | Q15: TA OK | R15: TA OK | S15: TA OK
A16: One-HUB-EOP-12 | B16: Editorial Overview Page | C16: S113 First Level Teaser | D16: Validation, that - a S113 with its items can be modify - arranges a headline and between 2 and 4 Editorial Teaser Elements | E16: S113 First Level Teaser Item: Heading Editorial Teaser Element 1 Editorial Teaser Element 2 | F16: Yes | G16: Completed | Q16: TA OK | S16: TA OK
A17: One-HUB-EOP-12-01 | B17: Editorial Overview Page | C17: S113 First Level Teaser | D17: Validation, that - the S113 First Level Teaser is displayed on the publisher | E17: S113 First Level Teaser Item: Heading Editorial Teaser Element 1 Editorial Teaser Element 2 | F17: Yes | G17: Completed | K17: TA OK | L17: TA OK | M17: TA OK | N17: TA OK | O17: TA OK | P17: TA OK | Q17: TA OK | R17: TA OK | S17: TA OK
A18: One-HUB-EOP-13 | B18: Editorial Overview Page | C18: S115 Focus Teaser Section | D18: Validation, that - a S115 with its items can be modify - arranges a focus teaser element | E18: S115 Focus Teaser Section Editorial Teaser Element 1 | F18: Yes | G18: Completed | Q18: TA OK | S18: TA OK
A19: One-HUB-EOP-13-01 | B19: Editorial Overview Page | C19: S115 Focus Teaser Section | D19: Validation, that - the S115 Focus Teaser Section is displayed on the publisher | E19: S115 Focus Teaser Section Editorial Teaser Element 1 | F19: Yes | G19: Completed | K19: TA OK | L19: TA OK | M19: TA OK | N19: TA OK | O19: TA OK | P19: TA OK | Q19: TA OK | R19: TA OK | S19: TA OK
A20: One-HUB-EOP-14 | B20: Editorial Overview Page | C20: S123 Second Level Teaser Section | D20: Validation, that - a S123 with its items can be modify - arranges an optional heading, copy item and a grid-like view of teasers | E20: S123 Second Level Teaser Section Item: Heading Item: I101Copy Item Item: grid-like view teaser | F20: Yes | G20: Completed | Q20: TA OK | S20: TA OK
A21: One-HUB-EOP-14-01 | B21: Editorial Overview Page | C21: S123 Second Level Teaser Section | D21: Validation, that - the S123 Second Level Teaser Section is displayed on the publisher | E21: S123 Second Level Teaser Section Item: Heading Item: I101Copy Item Item: grid-like view teaser | F21: Yes | G21: Completed | K21: TA OK | L21: TA OK | M21: TA OK | N21: TA OK | O21: TA OK | P21: TA OK | Q21: TA OK | R21: TA OK | S21: TA OK
A22: One-HUB-EOP-15 | B22: Editorial Overview Page | C22: S116 Section Group | D22: Validation, that - a S116 with its items can be modify - arranges a headline and sections | E22: S116 Section Group S108 Editorial Teaser Section Item: Heading Item: Editorial teaser 1 Item: Editorial teaser 2 Item: Editorial teaser 3 S101 Heading Section Item: Heading Item: I101Copy Item | F22: Yes | G22: Completed | Q22: TA OK | S22: TA OK
A23: One-HUB-EOP-15-01 | B23: Editorial Overview Page | C23: S116 Section Group | D23: Validation, that - the S116 Section Group is displayed on the publisher | E23: S116 Section Group S108 Editorial Teaser Section Item: Heading Item: Editorial teaser 1 Item: Editorial teaser 2 Item: Editorial teaser 3 S101 Heading Section Item: Heading Item: I101Copy Item | F23: Yes | G23: Completed | K23: TA OK | L23: TA OK | M23: TA OK | N23: TA OK | O23: TA OK | P23: TA OK | Q23: TA OK | R23: TA OK | S23: TA OK
A24: One-HUB-EOP-16 | B24: Editorial Overview Page | C24: S117 Accordion Section | D24: Validation, that - a S117 with its items can be modify - arranges a I117 accordion item | E24: S117 Accordion Section Item: Heading Item: I117Accordion Item 1 Item: Richtext Simple Item: Richtext Full Item: I117Accordion Item 2 Item: Richtext Simple Item: Richtext Full Item: I117Accordion Item 3 Item: Richtext Simple Item: Richtext Full | F24: Yes | G24: Completed | Q24: TA OK | S24: TA OK
A25: One-HUB-EOP-16-01 | B25: Editorial Overview Page | C25: S117 Accordion Section | D25: Validation, that - the S117 Accordion Section is displayed on the publisher | E25: S117 Accordion Section Item: Heading Item: I117Accordion Item 1 Item: Richtext Simple Item: Richtext Full Item: I117Accordion Item 2 Item: Richtext Simple Item: Richtext Full Item: I117Accordion Item 3 Item: Richtext Simple Item: Richtext Full | F25: Yes | G25: Completed | K25: TA OK | L25: TA OK | M25: TA OK | N25: TA OK | O25: TA OK | P25: TA OK | Q25: TA OK | R25: TA OK | S25: TA OK
A26: One-HUB-EOP-17 | B26: Editorial Overview Page | C26: S124 Table Section | D26: Validation, that - a S124 with its cells can be modify - arranges empty table, image table, merge column merge row and richtext table cell | E26: S124 Table Section Row Table Element 1: with 4 Richtext Table Cells Row Table Element 2: with 4 Empty Table Cells Row Table Element 3: with 4 Richtext Table Cells Row Table Element 4: with 4 Image Table Cells | F26: Yes | G26: Completed | Q26: TA OK | S26: TA OK
A27: One-HUB-EOP-17-01 | B27: Editorial Overview Page | C27: S124 Table Section | D27: Validation, that - the S124 Table SectionAccordion Section is displayed on the publisher | E27: S124 Table Section Row Table Element 1: with 4 Richtext Table Cells Row Table Element 2: with 4 Empty Table Cells Row Table Element 3: with 4 Richtext Table Cells Row Table Element 4: with 4 Image Table Cells | F27: Yes | G27: Completed | K27: TA OK | L27: TA OK | M27: TA OK | N27: TA OK | O27: TA OK | P27: TA OK | Q27: TA OK | R27: TA OK | S27: TA OK
A28: One-HUB-EOP-18 | B28: Editorial Overview Page | C28: S126 Iframe Integrator Section | D28: Validation, that - a S126 with its items can be modify - integrates an external website in a page | E28: S126 Iframe Integrator Section Item: external URL - https://webspecial.volkswagen.de/emobility/test-lsf - https://trml1m.axshare.com/#id=fup9js&p=page_1&c=1 - https://hef7jn.axshare.com/#id=ptypxa&p=page_1&c=1 Item: Iframe heights by breakpoints Item: Layout for the column | F28: Yes | G28: Completed | Q28: TA OK
A29: One-HUB-EOP-18-01 | B29: Editorial Overview Page | C29: S126 Iframe Integrator Section | D29: Validation, that - the S126 Iframe Integrator Section is displayed on the publisher | E29: S126 Iframe Integrator Section Item: external URL - https://webspecial.volkswagen.de/emobility/test-lsf - https://trml1m.axshare.com/#id=fup9js&p=page_1&c=1 - https://hef7jn.axshare.com/#id=ptypxa&p=page_1&c=1 Item: Iframe heights by breakpoints Item: Layout for the column | F29: Yes | G29: Completed | K29: TA OK | L29: TA OK | M29: TA OK | N29: TA OK | O29: TA OK | P29: TA OK | Q29: TA OK | R29: TA OK | S29: TA OK
A30: One-HUB-EOP-19 | B30: Editorial Overview Page | C30: S111 Pros and Cons Section | D30: Validation, that - a S111 with its items can be modify - arranges a pro / contra item with a headline, copy item, label, statement, description and image | E30: S111 Pros and Cons Sectio Item: Heading n Pro/Contra item Item: I101Copy Item Item: Richtext Simple Item: Richtext Simple Item: Richtext Simple Item: Richtext Simple Item: Richtext Full Item: image | F30: Yes | G30: Completed | Q30: TA OK
A31: One-HUB-EOP-19-01 | B31: Editorial Overview Page | C31: S111 Pros and Cons Section | D31: Validation, that - the S111 Pros and Cons Section is displayed on the publisher | E31: S111 Pros and Cons Sectio Item: Heading n Pro/Contra item Item: I101Copy Item Item: Richtext Simple Item: Richtext Simple Item: Richtext Simple Item: Richtext Simple Item: Richtext Full Item: image | F31: Yes | G31: Completed | K31: TA OK | L31: TA OK | M31: TA OK | N31: TA OK | O31: TA OK | P31: TA OK | Q31: TA OK | R31: TA OK | S31: TA OK
A32: One-HUB-EOP-20 | B32: Editorial Overview Page | C32: S112 Step By Step Section | D32: Validation, that - a S112 with its items can be modify - arranges a headline, copy item and I111 Step by Step Containerchild | E32: S112 Step By Step Section Item: Heading Item: I101Copy Item Item: StepbyStep Item 1 StepbyStep Item: Image StepbyStep Item: Richtext Simple Element StepbyStep Item: Richtext Full Item: StepbyStep Item 2 StepbyStep Item: Image StepbyStep Item: Richtext Full Item: StepbyStep Item 3 StepbyStep Item: Image StepbyStep Item: Richtext Full | F32: Yes | G32: Completed | Q32: TA OK
A33: One-HUB-EOP-20-01 | B33: Editorial Overview Page | C33: S112 Step By Step Section | D33: Validation, that - the S111 Pros and Cons Section is displayed on the publisher | E33: S112 Step By Step Section Item: Heading Item: I101Copy Item Item: StepbyStep Item 1 StepbyStep Item: Image StepbyStep Item: Richtext Simple Element StepbyStep Item: Richtext Full Item: StepbyStep Item 2 StepbyStep Item: Image StepbyStep Item: Richtext Full Item: StepbyStep Item 3 StepbyStep Item: Image StepbyStep Item: Richtext Full | F33: Yes | G33: Completed | K33: TA OK | L33: TA OK | M33: TA OK | N33: TA OK | O33: TA OK | P33: TA OK | Q33: TA OK | R33: TA OK | S33: TA OK
A34: One-HUB-EOP-21 | B34: Editorial Overview Page | C34: S106 Editorial Stage Section | D34: Validation, that - a S106 with its items can be deleted - arranges a headline, a media element and a copy item | E34: S106 Editorial Stage Section Item: Media Element Item: Heading Item: I101Copy Item | F34: Yes | G34: Completed | Q34: TA OK | S34: TA OK
A35: One-HUB-EOP-21-01 | B35: Editorial Overview Page | C35: S106 Editorial Stage Section | D35: Validation, that - the Showroom is displayed without S106 Editorial Stage Section on the publisher. | E35: S106 Editorial Stage Section Item: Media Element Item: Heading Item: I101Copy Item | F35: Yes | G35: Completed | K35: TA OK | L35: TA OK | M35: TA OK | N35: TA OK | O35: TA OK | P35: TA OK | Q35: TA OK | R35: TA OK | S35: TA OK
A36: One-HUB-EOP-22 | B36: Editorial Overview Page | C36: S113 First Level Teaser | D36: Validation, that - a S113 with its items can be deleted - arranges a headline and between 2 and 4 Editorial Teaser Elements | E36: S113 First Level Teaser Item: Heading Editorial Teaser Element 1 Editorial Teaser Element 2 | F36: Yes | G36: Completed | Q36: TA OK | S36: TA OK
A37: One-HUB-EOP-22-01 | B37: Editorial Overview Page | C37: S113 First Level Teaser | D37: Validation, that - the Showroom is displayed without S113 First Level Teaser on the publisher. | E37: S113 First Level Teaser Item: Heading Editorial Teaser Element 1 Editorial Teaser Element 2 | F37: Yes | G37: Completed | K37: TA OK | L37: TA OK | M37: TA OK | N37: TA OK | O37: TA OK | P37: TA OK | Q37: TA OK | R37: TA OK | S37: TA OK
A38: One-HUB-EOP-23 | B38: Editorial Overview Page | C38: S115 Focus Teaser Section | D38: Validation, that - a S115 with its items can be deleted - arranges a focus teaser element | E38: S115 Focus Teaser Section Editorial Teaser Element 1 | F38: Yes | G38: Completed | Q38: TA OK | S38: TA OK
A39: One-HUB-EOP-23-01 | B39: Editorial Overview Page | C39: S115 Focus Teaser Section | D39: Validation, that - the Showroom is displayed without S115 Focus Teaser Section on the publisher. | E39: S115 Focus Teaser Section Editorial Teaser Element 1 | F39: Yes | G39: Completed | K39: TA OK | L39: TA OK | M39: TA OK | N39: TA OK | O39: TA OK | P39: TA OK | Q39: TA OK | R39: TA OK | S39: TA OK
A40: One-HUB-EOP-24 | B40: Editorial Overview Page | C40: S123 Second Level Teaser Section | D40: Validation, that - a S123 with its items can be deleted - arranges an optional heading, copy item and a grid-like view of teasers | E40: S123 Second Level Teaser Section Item: Heading Item: I101Copy Item Item: grid-like view teaser | F40: Yes | G40: Completed | Q40: TA OK | S40: TA OK
...

Sheet Showroom Page
A1: =Homepage!A1 -> Testexecution Product Release Version: v3.198.276.122 Date Start: 30.06.2026 Date Ende: 06.07.2026 Test
A2: =Homepage!A2 -> Environment: https://ngw-stage.lighthouselabs.io/de/mofa.html
A3: Checkpoint | B3: Template | C3: Section | D3: Test goal (expected result) | E3: Section Items | F3: TA | G3: TA Status | H3: Example | I3: URL Testcontent | J3: Who | K3: iPhone 16 iOs v. 26 Safari/Mobile | L3: iPad iOs v. 26 Safari/Tablet | M3: MacBook Safari v. 12.1.2 | N3: Samsung Galaxy 8 Android v. IE v. 10.1.00.27 Chrome/Mobile | O3: Tablet Android v. Chrome v. 77 Chrome/Tablet | P3: Samsung Galaxy 8 Android Chrome v. 77 Chrome/Mobile | Q3: Chrome v. 84 Chrome/Desktop | R3: Microsoft Edge v. 44 Chrome/ Desktop | S3: FireFox v. 68 | T3: New Jira Ticket | U3: Existing Jira Ticket
A4: One-HUB-SR-01 | B4: Showroom Page | C4: S114 Product Experience Stage Section | D4: Validation, that - a S114 with its items can be created - arranges a 180 Degree Animation that takes proportions of entire screen and a headline - is saved | E4: S114 Product Experience Stage Section Item: 180 Degree Element Item: Heading | F4: Yes | G4: Completed | Q4: TA OK | S4: TA OK
A5: One-HUB-SR-01-01 | B5: Showroom Page | C5: S139 Basic Stage Section | D5: Validation, that - a S139 with its items can be created - a video with the same cover image can be maintained | E5: S139 Fullscreen Stage Section Item: Heading Item: Video Cover Image | F5: Yes | G5: Completed | Q5: TA OK | S5: TA OK
A6: One-HUB-SR-02 | B6: Showroom Page | C6: S128 Car Technical Data Section | D6: Validation, that - a S128 with its items can be created - is a content component for showrooms - shows a list of up to 2 key highlight technical facts about the car / salegroup / carline - shows a list of up to 6 key technical data facts about the car / salegroup / carline - is saved | E6: S128 Car Technical Data Section Item: Technical Car Fact 1 Item: Technical Car Fact 2 Item: Technical Car Fact 3 Item: Technical Car Fact 4 Item: Technical Car Fact 5 Item: Optional Button | F6: Yes | G6: Completed | Q6: TA OK | S6: TA OK
A7: One-HUB-SR-02-1 | B7: Showroom Page | C7: S128 Car Technical Data Section | D7: Validation, that - Car Technical Data Feature app can be opened with CTA - in Publish text in data tiles is not cut-off when exceeding three lines | E7: S128 Car Technical Data Section | F7: No | I7: Der Taigo
A8: One-HUB-SR-02-2 | B8: Showrom Page | C8: S128 Car Technical Data Section | D8: Validation, that - a S128 with primary, secondary and text link can be created - Buttons are positioned horizontal/vertical - is saved | E8: S128 Car Technical Data Section Item: Primary Button Item: Second Button Item: Text Link | F8: Yes | G8: Completed | Q8: TA OK | S8: TA OK
A9: One-HUB-SR-03 | B9: Showroom Page | C9: S108 Editorial Teaser Section | D9: Validation, that - a S108 with its items can be created - arranges 3 or 6 teaser elements - is saved | E9: S108 Editorial Teaser Section Item: Heading Editorial Teaser Element 1 Editorial Teaser Element 2 Editorial Teaser Element 3 | F9: Yes | G9: Completed | Q9: TA OK | S9: TA OK
A10: One-HUB-SR-04 | B10: Showroom Page | C10: S101 Heading Section | D10: Validation, that - a S101 with its items can be created - arranges a headline with a copy item - is saved | E10: S101 Heading Section Item: Heading Item: I101Copy Item | F10: Yes | G10: Completed | Q10: TA OK | S10: TA OK
A11: One-HUB-SR-05 | B11: Showroom Page | C11: S116 Section Group | D11: Validation, that - a S116 with its items can be created - arranges a headline and several sections - is saved | E11: S116 Section Group S101 Heading Section Item: Heading Item: I101Copy Item S102 Single Column Section Item: Heading I101 Copy Item I102 Quote Item I103 Statement Item I106 Media Single Item I108 Link List Item S102 Single Column Section Item: Heading I101 Copy Item I102 Quote Item I103 Statement Item I106 Media Single Item I108 Link List Item S125 Highlight Feature Section Carfeature 1 Item: Disclaimer Reference and add Legal Entity | F11: Yes | G11: Completed | Q11: TA OK | S11: TA OK
A12: One-HUB-SR-06 | B12: Showroom Page | C12: S102 Two Columns Section | D12: Validation, that - a S102 with its items can be created - arranges 2 Colums for items - Items: I101 copy item; I102 quote item;I103 statement item;I106 media single item; I126 link list item - is saved | E12: S102 Two Columns Section I101 Copy Item (left) I102 Quote Item (left) I103 Statement Item (left) I106 Media Single Item (left) I108 Link List Item (left) I101 Copy Item (right) I102 Quote Item (right) I103 Statement Item (right) I106 Media Single Item (right) I108 Link List Item (right) | F12: Yes | G12: Completed | Q12: TA OK | S12: TA OK
A13: One-HUB-SR-07 | B13: Showroom Page | C13: S125 Highlight Feature Section | D13: Validation, that - a S125 with its items can be created - consists of two modules: highlight accordion module and highlight media gallery module - highlight accordion module arranges two base elements: a headline copy(heading element and copy item) and a label(Richtext Simple Element) - media gallery module arranges a collection of up to 5 media elements - is saved | E13: S125 Highlight Feature Section Car Feature 1 Car Feature 2 Car Feature 3 Car Feature 4 | F13: Yes | G13: Completed | Q13: TA OK | S13: TA OK
A14: One-HUB-SR-08 | B14: Showroom Page | C14: S122 Feature App Section | D14: Validation, that - a S122 with its items can be created - arranges upcoming feature apps - is saved | E14: S122 Feature App Section Feature App: Configure | F14: Yes | G14: Completed | Q14: TA OK | S14: TA OK
A15: One-HUB-SR-09 | B15: Showroom Page | C15: S105 Mood Gallery Section | D15: Validation, that - a S105 with its items can be created - arranges a headline and up to 5 media elements - is saved | E15: S105 Mood Gallery Section Item: Heading Item: Media Element 1 Item: Media Element 2 Item: Media Element 3 Item: Media Element 4 Item: Media Element 5 | F15: Yes | G15: Completed | Q15: TA OK | S15: TA OK
A16: One-HUB-SR-10 | B16: Showroom Page | C16: S110 Highlight Teaser Section | D16: Validation, that - a S110 with its items can be created - arranges between 3 and 5 Editorial Teaser Elements - is saved | E16: S110 Highlight Teaser Section Item: Heading Editorial Teaser Element 1 Editorial Teaser Element 2 Editorial Teaser Element 3 | F16: Yes | G16: Completed | Q16: TA OK | S16: TA OK
A17: One-HUB-SR-11 | B17: Showroom Page | C17: S127 Feature Cluster Section | D17: Validation, that - a S127 with its items can be created - is a content component for showrooms - shows a list of Car Feature Categories and display each category with a list of links to Car Features or Content Layers, that will be opened as layers - is saved | E17: S127 Feature Cluster Section Item: Heading I101 Copy Item Car Feature Category Item 1 Car Feature Category Item 2 Car Feature Category Item 3 Car Feature Category Item 4 | F17: Yes | G17: Completed | Q17: TA OK | S17: TA OK
A18: One-HUB-SR-12 | B18: Showroom Page | C18: S130 USP Section | D18: Validation, that - a S130 with its items can be created - is a content component for showrooms - arrenges the 3 main USPs of a certain sales group - is saved | E18: S130 USP Section Item: Media Element 1: Image Item: Heading 1 Item: Copy Text 1 Item: Link 1: External Link/Internal Link Item: Media Element 2: Animation Item: Heading 2 Item: Copy Text 2 Item: Link 2: Layer Item: Media Element 3: Animation Item: Heading 3 Item: Copy Text 3 Item: Media Element 1: 180 Degree Element Properties: Tab Media interaction element Switch on: Show media interaction element Label: Media interaction elements right Label: Media interaction elements left Item: Link 3: Download | F18: Yes | G18: Completed | Q18: TA OK | S18: TA OK
A19: One-HUB-SR-37 | B19: Showroom Page | C19: S138 Scrollytelling | D19: Validation that - a S138 with can be created - Scrollytelling element can be inserted with: Scrollytelling video - Items can be inserted with: Heading Copy item | E19: S138 Scrollytelling Section | F19: Yes | G19: Completed | Q19: TA OK | S19: TA OK
... A21: One-HUB-SR-13 | B21: Showroom Page | C21: S114 Product Experience Stage Section | D21: Validation, that - a S114 with its items can be modified - arranges a 180 Degree Animation that takes proportions of entire screen and a headline | E21: S114 Product Experience Stage Section Item: 180 Degree Element Item: Heading | F21: Yes | G21: Completed | Q21: TA OK | S21: TA OK
A22: One-HUB-SR-13-01 | B22: Showroom Page | C22: S114 Product Experience Stage Section | D22: Validation, that - the S114 Product Experience Stage Section is displayed on the publisher | E22: S114 Product Experience Stage Section Item: 180 Degree Element Item: Heading | F22: Yes | G22: Completed | K22: TA OK | L22: TA OK | M22: TA OK | N22: TA OK | O22: TA OK | P22: TA OK | Q22: TA OK | S22: TA OK
A23: One-HUB-SR-14 | B23: Showroom Page | C23: S128 Car Technical Data Section | D23: Validation, that - a S128 with its items can be modified - is a content component for showrooms - shows a list of up to 10 key technical facts about the car / salegroup / carline | E23: S128 Car Technical Data Section Item: Technical Car Fact 1 Item: Technical Car Fact 2 Item: Technical Car Fact 3 Item: Technical Car Fact 4 Item: Technical Car Fact 5 Item: optional Button | F23: Yes | G23: Completed | Q23: TA OK | S23: TA OK
A24: One-HUB-SR-14-01 | B24: Showroom Page | C24: S128 Car Technical Data Section | D24: Validation, that - the S128 Car Technical Data Section is displayed on the publisher | E24: S128 Car Technical Data Section Item: Technical Car Fact 1 Item: Technical Car Fact 2 Item: Technical Car Fact 3 Item: Technical Car Fact 4 Item: Technical Car Fact 5 Item: optional Button | F24: Yes | G24: Completed | K24: TA OK | L24: TA OK | M24: TA OK | N24: TA OK | O24: TA OK | P24: TA OK | Q24: TA OK | S24: TA OK
A25: One-HUB-SR-15 | B25: Showroom Page | C25: S108 Editorial Teaser Section | D25: Validation, that - a S108 with its items can be modified - arranges 3 or 6 teaser elements | E25: S108 Editorial Teaser Section Item: Heading Editorial Teaser Element 1 Editorial Teaser Element 2 Editorial Teaser Element 3 | F25: Yes | G25: Completed | Q25: TA OK | S25: TA OK
A26: One-HUB-SR-15-01 | B26: Showroom Page | C26: S108 Editorial Teaser Section | D26: Validation, that - S108 Editorial Teaser Section is displayed on the publisher. | E26: S108 Editorial Teaser Section Item: Heading Editorial Teaser Element 1 Editorial Teaser Element 2 Editorial Teaser Element 3 | F26: Yes | G26: Completed | K26: TA OK | L26: TA OK | M26: TA OK | N26: TA OK | O26: TA OK | P26: TA OK | Q26: TA OK | S26: TA OK
A27: One-HUB-SR-16 | B27: Showroom Page | C27: S101 Heading Section | D27: Validation, that - a S101 with its items can be modified - arranges a headline with a copy item | E27: S101 Heading Section Item: Heading Item: I101Copy Item | F27: Yes | G27: Completed | Q27: TA OK | S27: TA OK
A28: One-HUB-SR-16-01 | B28: Showroom Page | C28: S101 Heading Section | D28: Validation, that - the S101 Heading Section is displayed on the publisher | E28: S101 Heading Section Item: Heading Item: I101Copy Item | F28: Yes | G28: Completed | K28: TA OK | L28: TA OK | M28: TA OK | N28: TA OK | O28: TA OK | P28: TA OK | Q28: TA OK | S28: TA OK
A29: One-HUB-SR-17 | B29: Showroom Page | C29: S116 Section Group | D29: Validation, that - a S116 with its items can be modified - arranges a headline and several sections | E29: S116 Section Group S101 Heading Section Item: Heading Item: I101Copy Item S102 Single Column Section Item: Heading I101 Copy Item I102 Quote Item I103 Statement Item I106 Media Single Item I108 Link List Item S102 Single Column Section Item: Heading I101 Copy Item I102 Quote Item I103 Statement Item I106 Media Single Item I108 Link List Item S125 Highlight Feature Section Carfeature 1 Item: Disclaimer Reference and add Legal Entity | F29: Yes | G29: Completed | Q29: TA OK | S29: TA OK
A30: One-HUB-SR-17-01 | B30: Showroom Page | C30: S116 Section Group | D30: Validation, that - the S116 Section Group is displayed on the publisher | E30: S116 Section Group S101 Heading Section Item: Heading Item: I101Copy Item S102 Single Column Section Item: Heading I101 Copy Item I102 Quote Item I103 Statement Item I106 Media Single Item I108 Link List Item S102 Single Column Section Item: Heading I101 Copy Item I102 Quote Item I103 Statement Item I106 Media Single Item I108 Link List Item S125 Highlight Feature Section Carfeature 1 Item: Disclaimer Reference and add Legal Entity | F30: Yes | G30: Completed | K30: TA OK | L30: TA OK | M30: TA OK | N30: TA OK | O30: TA OK | P30: TA OK | Q30: TA OK | S30: TA OK
A31: One-HUB-SR-18 | B31: Showroom Page | C31: S102 Two Columns Section | D31: Validation, that - a S102 with its items can be modified - arranges 2 Colums for items - Items: I101 copy item; I102 quote item;I103 statement item;I106 media single item ;I126 link list item | E31: S102 Two Columns Section I101 Copy Item (left) I102 Quote Item (left) I103 Statement Item (left) I106 Media Single Item (left) I108 Link List Item (left) I101 Copy Item (right) I102 Quote Item (right) I103 Statement Item (right) I106 Media Single Item (right) I108 Link List Item (right) | F31: Yes | G31: Completed | Q31: TA OK | S31: TA OK
A32: One-HUB-SR-18-01 | B32: Showroom Page | C32: S102 Two Columns Section | D32: Validation, that - the S102 Two Columns Section is displayed on the publisher | E32: S102 Two Columns Section I101 Copy Item (left) I102 Quote Item (left) I103 Statement Item (left) I106 Media Single Item (left) I108 Link List Item (left) I101 Copy Item (right) I102 Quote Item (right) I103 Statement Item (right) I106 Media Single Item (right) I108 Link List Item (right) | F32: Yes | G32: Completed | K32: TA OK | L32: TA OK | M32: TA OK | N32: TA OK | O32: TA OK | P32: TA OK | Q32: TA OK | S32: TA OK
A33: One-HUB-SR-19 | B33: Showroom Page | C33: S125 Highlight Feature Section | D33: Validation, that - a S125 with its items can be modified - consists of two modules: highlight accordion module and highlight media gallery module - highlight accordion module arranges two base elements: a headline copy(heading element and copy item) and a label(Richtext Simple Element) - media gallery module arranges a collection of up to 5 media elements | E33: S125 Highlight Feature Section Car Feature 1 Car Feature 2 Car Feature 3 Car Feature 4 | F33: Yes | G33: Completed | Q33: TA OK | S33: TA OK
A34: One-HUB-SR-19-01 | B34: Showroom Page | C34: S125 Highlight Feature Section | D34: Validation, that - the S125 Highlight Feature Section is displayed on the publisher | E34: S125 Highlight Feature Section Car Feature 1 Car Feature 2 Car Feature 3 Car Feature 4 | F34: Yes | G34: Completed | K34: TA OK | L34: TA OK | M34: TA OK | N34: TA OK | O34: TA OK | P34: TA OK | Q34: TA OK | S34: TA OK
A35: One-HUB-SR-20 | B35: Showroom Page | C35: S122 Feature App Section | D35: Validation, that - a S122 with its items can be modified - arranges upcoming feature apps | E35: S122 Feature App Section Feature App: Configure | F35: Yes | G35: Completed | Q35: TA OK | S35: TA OK
A36: One-HUB-SR-20-01 | B36: Showroom Page | C36: S122 Feature App Section | D36: Validation, that - the S122 Feature App Section is displayed on the publisher | E36: S122 Feature App Section Feature App: Configure | F36: Yes | G36: Completed | K36: TA OK | L36: TA OK | M36: TA OK | N36: TA OK | O36: TA OK | P36: TA OK | Q36: TA OK | S36: TA OK
A37: One-HUB-SR-21 | B37: Showroom Page | C37: S105 Mood Gallery Section | D37: Validation, that - a S105 with its items can be modified - arranges a headline and up to 5 media elements | E37: S105 Mood Gallery Section Item: Heading Item: Media Element 1 Item: Media Element 2 Item: Media Element 3 Item: Media Element 4 Item: Media Element 5 | F37: Yes | G37: Completed | Q37: TA OK | S37: TA OK
A38: One-HUB-SR-21-01 | B38: Showroom Page | C38: S105 Mood Gallery Section | D38: Validation, that - the S105 Mood Gallery Section is displayed on the publisher | E38: S105 Mood Gallery Section Item: Heading Item: Media Element 1 Item: Media Element 2 Item: Media Element 3 Item: Media Element 4 Item: Media Element 5 | F38: Yes | G38: Completed | K38: TA OK | L38: TA OK | M38: TA OK | N38: TA OK | O38: TA OK | P38: TA OK | Q38: TA OK | S38: TA OK
A39: One-HUB-SR-22 | B39: Showroom Page | C39: S110 Highlight Teaser Section | D39: Validation, that - a S110 with its items can be modified - arranges between 3 and 5 Editorial Teaser Elements | E39: S110 Highlight Teaser Section Item: Heading Editorial Teaser Element 1 Editorial Teaser Element 2 Editorial Teaser Element 3 | F39: Yes | G39: Completed | Q39: TA OK | S39: TA OK
A40: One-HUB-SR-22-01 | B40: Showroom Page | C40: S110 Highlight Teaser Section | D40: Validation, that - the S110 Highlight Teaser Section is displayed on the publisher | E40: S110 Highlight Teaser Section Item: Heading Editorial Teaser Element 1 Editorial Teaser Element 2 Editorial Teaser Element 3 | F40: Yes | G40: Completed | K40: TA OK | L40: TA OK | M40: TA OK | N40: TA OK | O40: TA OK | P40: TA OK | Q40: TA OK | S40: TA OK
A41: One-HUB-SR-23 | B41: Showroom Page | C41: S127 Feature Cluster Section | D41: Validation, that - a S127 with its items can be modified - is a content component for showrooms - shows a list of Car Feature Categories and display each category with a list of links to Car Features or Content Layers, that will be opened as layers | E41: S127 Feature Cluster Section Item: Heading I101 Copy Item Car Feature Category Item 1 Car Feature Category Item 2 Car Feature Category Item 3 Car Feature Category Item 4 | F41: Yes | G41: Completed | Q41: TA OK | S41: TA OK
...

Sheet Editorial Page
A1: =Homepage!A1 -> Testexecution Product Release Version: v3.198.276.122 Date Start: 30.06.2026 Date Ende: 06.07.2026 Test
A2: =Homepage!A2 -> Environment: https://ngw-stage.lighthouselabs.io/de/mofa.html
A3: Checkpoint | B3: Template | C3: Section | D3: Test goal (expected result) | E3: Section Items | F3: TA | G3: TA Status | H3: Example | I3: URL Testcontent | J3: Who | K3: iPhone 16 iOs v. 26 Safari/Mobile | L3: iPad iOs v. 26 Safari/Tablet | M3: MacBook Safari v. 12.1.2 | N3: Samsung Galaxy 8 Android v. IE v. 10.1.00.27 Chrome/Mobile | O3: Tablet Android v. Chrome v. 77 Chrome/Tablet | P3: Samsung Galaxy 8 Android Chrome v. 77 Chrome/Mobile | Q3: Chrome v. 84 Chrome/Desktop | R3: Microsoft Edge v. 44 Chrome/ Desktop | S3: FireFox v. 68 | T3: New Jira Ticket | U3: Existing Jira Ticket
A4: One-HUB-EP-01 | B4: Editorial Page | C4: S109 Answers Stage | D4: Validation, that - a S109 with its items can be created - arranges a headline and an image illustration - is saved | E4: S109 Answers Stage Item: Heading Item: I101Copy Item Item: Image Illustration Reading Time | F4: Yes | G4: Completed | Q4: TA OK | S4: TA OK
A5: One-HUB-EP-02 | B5: Editorial Page | C5: S101 Heading Section | D5: Validation, that - a S101 with its items can be created - arranges a headline with a copy item - is saved | E5: S101 Heading Section Item: Heading Item: I101Copy Item | F5: Yes | G5: Completed | Q5: TA OK | S5: TA OK
A6: One-HUB-EP-03 | B6: Editorial Page | C6: S102 Single Column Section | D6: Validation, that - a S102 with its items can be created - arranges a headline and a column for items - Items: I101 copy item; I102 quote item;I103 statement item;I106 media single item ;I126 link list item - is saved | E6: S102 Single Column Section Item: Heading Item: I101Copy Item I102 Quote Item I103 Statement Item I106 Media Single Image Only Item I108 Link List Item | F6: Yes | G6: Completed | Q6: TA OK | S6: TA OK
A7: One-HUB-EP-04 | B7: Editorial Page | C7: S102 Two Columns Section | D7: Validation, that - a S102 with its items can be created - arranges 2 Colums for items - Items: I101 copy item; I102 quote item;I103 statement item;I106 media single item ;I126 link list item - is saved | E7: S102 Two Columns Section I101Copy Item I102 Quote Item I103 Statement Item I106 Media Single Image Only Item I108 Link List Item | F7: Yes | G7: Completed | Q7: TA OK | S7: TA OK
A8: One-HUB-EP-05 | B8: Editorial Page | C8: S103 Copy Inset Media Section | D8: Validation, that - a S103 with its items can be created - arranges a headline, copy item and a media element - is saved | E8: S103 Copy Inset Media Section Item: Heading Item: I101Copy Item Item: Media Element | F8: Yes | G8: Completed | Q8: TA OK | S8: TA OK
A9: One-HUB-EP-06 | B9: Editorial Page | C9: S105 Mood Gallery Section | D9: Validation, that - a S105 with its items can be created - arranges a headline and up to 5 media elements - is saved | E9: S105 Mood Gallery Section Item: Heading Item: Media Element 1 Item: Media Element 2 Item: Media Element 3 | F9: Yes | G9: Completed | Q9: TA OK | S9: TA OK
A10: One-HUB-EP-07 | B10: Editorial Page | C10: S107 Intro Copy Section | D10: Validation, that - a S107 with its items can be created - arranges copy item in a specific layout - is saved | E10: S107 Intro Copy Section Item: I101Copy Item | F10: Yes | G10: Completed | Q10: TA OK | S10: TA OK
A11: One-HUB-EP-08 | B11: Editorial Page | C11: S108 Editorial Teaser Section | D11: Validation, that - a S108 with its items can be created - arranges 3 or 6 teaser elements - is saved | E11: S108 Editorial Teaser Section Item: Heading Editorial Teaser Element 1 Editorial Teaser Element 2 Editorial Teaser Element 3 | F11: Yes | G11: Completed | Q11: TA OK | S11: TA OK
A12: One-HUB-EP-09 | B12: Editorial Page | C12: S116 Section Group | D12: Validation, that - a S116 with its items can be created - arranges a headline and several sections - is saved | E12: S116 Section Group S102 Single Column Section Item: Heading I101Copy Item I102 Quote Item I103 Statement Item I106 Media Single Image Only Item I108 Link List Item | F12: Yes | G12: Completed | Q12: TA OK | S12: TA OK
A13: One-HUB-EP-10 | B13: Editorial Page | C13: S117 Accordion Section | D13: Validation, that - a S117 with its items can be created - arranges a list of I117 accordion itemsg - is saved | E13: S117 Accordion Section Item: Heading Richtext Simple Element Richtext Full Element | F13: Yes | G13: Completed | Q13: TA OK | S13: TA OK
A14: One-HUB-EP-11 | B14: Editorial Page | C14: S118 Countdown section | D14: Validation, that - a S118 with its items can be created - the countdown section consists of two states: a countdown module and prebooking teaser (after the countdown is finished) - the countdown element arranges a background image, headline, copy-text, countdown, CTA button - the pre-booking element arranges a background image, headline, richtext simple, icon bullet points with icons and CTA button - is saved | E14: Countdown Element Item: Heading I101Copy Item CTA Button Item: Image Countdown element: date Pre-Booking Element Item: Heading Item: Richtext Simple Icon Bullet Point Element 1: with CAR_FRONT Icon Icon Bullet Point Element 2: with CONTACT_DEALER Icon Icon Bullet Point Element 3: with DOWNLOAD Icon Icon Bullet Point Element 4: with MAIL Icon Icon Bullet Point Element 5: with CALENDAR Icon Icon Bullet Point Element 6: with BROCHURE Icon CTA Button Item: Image | F14: Yes | G14: Completed | Q14: TA OK | S14: TA OK
A15: One-HUB-EP-12 | B15: Editorial Page | C15: S119 Newsletter Signup Section | D15: Validation, that - a S119 with its items can be created - arranges a headline, a copy item and a CTA Button which provides a link to a newsletter signup form - is saved | E15: S119 Newsletter Signup Section Item: Heading Item: I101Copy Item | F15: Yes | G15: Completed | Q15: TA OK | S15: TA OK
A16: One-HUB-EP-13 | B16: Editorial Page | C16: S109 Answers Stage | D16: Validation, that - a S109 with its items can be modified - arranges a headline and an image illustration | E16: S109 Answers Stage Item: Heading Item: I101Copy Item Item: Image Illustration Reading Time | F16: Yes | G16: Completed | Q16: TA OK | S16: TA OK
A17: One-HUB-EP-13-01 | B17: Editorial Page | C17: S109 Answers Stage | D17: Validation, that - the S109 Answers Stage is displayed on the publisher | E17: S109 Answers Stage Item: Heading Item: I101Copy Item Item: Image Illustration Reading Time | F17: Yes | G17: Completed | J17: TA OK | K17: TA OK | L17: TA OK | M17: TA OK | N17: TA OK | O17: TA OK | P17: TA OK | Q17: TA OK | R17: TA OK | S17: TA OK
A18: One-HUB-EP-14 | B18: Editorial Page | C18: S101 Heading Section | D18: Validation, that - a S101 with its items can be modified - arranges a headline with a copy item | E18: S101 Heading Section Item: Heading Item: I101Copy Item | F18: Yes | G18: Completed | Q18: TA OK | S18: TA OK
A19: One-HUB-EP-14-01 | B19: Editorial Page | C19: S101 Heading Section | D19: Validation, that - the S101 Heading Section is displayed on the publisher | E19: S101 Heading Section Item: Heading Item: I101Copy Item | F19: Yes | G19: Completed | J19: TA OK | K19: TA OK | L19: TA OK | M19: TA OK | N19: TA OK | O19: TA OK | P19: TA OK | Q19: TA OK | S19: TA OK
A20: One-HUB-EP-15 | B20: Editorial Page | C20: S102 Single Column Section | D20: Validation, that - a S102 with its items can be modified - arranges a headline and a column for items - Items: I101 copy item; I102 quote item;I103 statement item;I106 media single item ;I126 link list item | E20: S102 Single Column Section Item: Heading Item: I101Copy Item I102 Quote Item I103 Statement Item I106 Media Single Image Only Item I108 Link List Item | F20: Yes | G20: Completed | Q20: TA OK | S20: TA OK
A21: One-HUB-EP-15-01 | B21: Editorial Page | C21: S102 Single Column Section | D21: Validation, that - the S102 Single Column Sectionis displayed on the publisher | E21: S102 Single Column Section Item: Heading Item: I101Copy Item I102 Quote Item I103 Statement Item I106 Media Single Image Only Item I108 Link List Item | F21: Yes | G21: Completed | J21: TA OK | K21: TA OK | L21: TA OK | M21: TA OK | N21: TA OK | O21: TA OK | P21: TA OK | Q21: TA OK | S21: TA OK
A22: One-HUB-EP-16 | B22: Editorial Page | C22: S102 Two Columns Section | D22: Validation, that - a S102 with its items can be modified - arranges 2 Colums for items - Items: I101 copy item; I102 quote item;I103 statement item;I106 media single item ;I126 link list item | E22: S102 Two Columns Section I101Copy Item I102 Quote Item I103 Statement Item I106 Media Single Image Only Item I108 Link List Item | F22: Yes | G22: Completed | Q22: TA OK | S22: TA OK
